Traceback (most recent call last):
  File "/home/ubuntu/.local/bin/pipenv", line 11, in <module>
    sys.exit(cli())
  File "/home/ubuntu/.local/lib/python3.6/site-packages/pipenv/vendor/click/core.py", line 764, in __call__
    return self.main(*args, **kwargs)
  File "/home/ubuntu/.local/lib/python3.6/site-packages/pipenv/vendor/click/core.py", line 717, in main
    rv = self.invoke(ctx)
  File "/home/ubuntu/.local/lib/python3.6/site-packages/pipenv/vendor/click/core.py", line 1137, in invoke
    return _process_result(sub_ctx.command.invoke(sub_ctx))
  File "/home/ubuntu/.local/lib/python3.6/site-packages/pipenv/vendor/click/core.py", line 956, in invoke
    return ctx.invoke(self.callback, **ctx.params)
  File "/home/ubuntu/.local/lib/python3.6/site-packages/pipenv/vendor/click/core.py", line 555, in invoke
    return callback(*args, **kwargs)
  File "/home/ubuntu/.local/lib/python3.6/site-packages/pipenv/vendor/click/decorators.py", line 64, in new_func
    return ctx.invoke(f, obj, *args, **kwargs)
  File "/home/ubuntu/.local/lib/python3.6/site-packages/pipenv/vendor/click/core.py", line 555, in invoke
    return callback(*args, **kwargs)
  File "/home/ubuntu/.local/lib/python3.6/site-packages/pipenv/cli/command.py", line 405, in run
    from ..core import do_run
  File "/home/ubuntu/.local/lib/python3.6/site-packages/pipenv/core.py", line 22, in <module>
    from .project import Project, SourceNotFound
  File "/home/ubuntu/.local/lib/python3.6/site-packages/pipenv/project.py", line 110, in <module>
    raise RuntimeError("Given PIPENV_PIPFILE is not found!")
RuntimeError: Given PIPENV_PIPFILE is not found!
Traceback (most recent call last):
  File "/usr/local/bin/pipenv", line 11, in <module>
    sys.exit(cli())
  File "/home/ubuntu/.local/lib/python3.6/site-packages/pipenv/vendor/click/core.py", line 764, in __call__
    return self.main(*args, **kwargs)
  File "/home/ubuntu/.local/lib/python3.6/site-packages/pipenv/vendor/click/core.py", line 717, in main
    rv = self.invoke(ctx)
  File "/home/ubuntu/.local/lib/python3.6/site-packages/pipenv/vendor/click/core.py", line 1137, in invoke
    return _process_result(sub_ctx.command.invoke(sub_ctx))
  File "/home/ubuntu/.local/lib/python3.6/site-packages/pipenv/vendor/click/core.py", line 956, in invoke
    return ctx.invoke(self.callback, **ctx.params)
  File "/home/ubuntu/.local/lib/python3.6/site-packages/pipenv/vendor/click/core.py", line 555, in invoke
    return callback(*args, **kwargs)
  File "/home/ubuntu/.local/lib/python3.6/site-packages/pipenv/vendor/click/decorators.py", line 64, in new_func
    return ctx.invoke(f, obj, *args, **kwargs)
  File "/home/ubuntu/.local/lib/python3.6/site-packages/pipenv/vendor/click/core.py", line 555, in invoke
    return callback(*args, **kwargs)
  File "/home/ubuntu/.local/lib/python3.6/site-packages/pipenv/cli/command.py", line 405, in run
    from ..core import do_run
  File "/home/ubuntu/.local/lib/python3.6/site-packages/pipenv/core.py", line 22, in <module>
    from .project import Project, SourceNotFound
  File "/home/ubuntu/.local/lib/python3.6/site-packages/pipenv/project.py", line 110, in <module>
    raise RuntimeError("Given PIPENV_PIPFILE is not found!")
RuntimeError: Given PIPENV_PIPFILE is not found!
Traceback (most recent call last):
  File "/usr/local/bin/pipenv", line 11, in <module>
    sys.exit(cli())
  File "/home/ubuntu/.local/lib/python3.6/site-packages/pipenv/vendor/click/core.py", line 764, in __call__
    return self.main(*args, **kwargs)
  File "/home/ubuntu/.local/lib/python3.6/site-packages/pipenv/vendor/click/core.py", line 717, in main
    rv = self.invoke(ctx)
  File "/home/ubuntu/.local/lib/python3.6/site-packages/pipenv/vendor/click/core.py", line 1137, in invoke
    return _process_result(sub_ctx.command.invoke(sub_ctx))
  File "/home/ubuntu/.local/lib/python3.6/site-packages/pipenv/vendor/click/core.py", line 956, in invoke
    return ctx.invoke(self.callback, **ctx.params)
  File "/home/ubuntu/.local/lib/python3.6/site-packages/pipenv/vendor/click/core.py", line 555, in invoke
    return callback(*args, **kwargs)
  File "/home/ubuntu/.local/lib/python3.6/site-packages/pipenv/vendor/click/decorators.py", line 64, in new_func
    return ctx.invoke(f, obj, *args, **kwargs)
  File "/home/ubuntu/.local/lib/python3.6/site-packages/pipenv/vendor/click/core.py", line 555, in invoke
    return callback(*args, **kwargs)
  File "/home/ubuntu/.local/lib/python3.6/site-packages/pipenv/cli/command.py", line 405, in run
    from ..core import do_run
  File "/home/ubuntu/.local/lib/python3.6/site-packages/pipenv/core.py", line 22, in <module>
    from .project import Project, SourceNotFound
  File "/home/ubuntu/.local/lib/python3.6/site-packages/pipenv/project.py", line 110, in <module>
    raise RuntimeError("Given PIPENV_PIPFILE is not found!")
RuntimeError: Given PIPENV_PIPFILE is not found!
Traceback (most recent call last):
  File "/usr/local/bin/pipenv", line 11, in <module>
    sys.exit(cli())
  File "/home/ubuntu/.local/lib/python3.6/site-packages/pipenv/vendor/click/core.py", line 764, in __call__
    return self.main(*args, **kwargs)
  File "/home/ubuntu/.local/lib/python3.6/site-packages/pipenv/vendor/click/core.py", line 717, in main
    rv = self.invoke(ctx)
  File "/home/ubuntu/.local/lib/python3.6/site-packages/pipenv/vendor/click/core.py", line 1137, in invoke
    return _process_result(sub_ctx.command.invoke(sub_ctx))
  File "/home/ubuntu/.local/lib/python3.6/site-packages/pipenv/vendor/click/core.py", line 956, in invoke
    return ctx.invoke(self.callback, **ctx.params)
  File "/home/ubuntu/.local/lib/python3.6/site-packages/pipenv/vendor/click/core.py", line 555, in invoke
    return callback(*args, **kwargs)
  File "/home/ubuntu/.local/lib/python3.6/site-packages/pipenv/vendor/click/decorators.py", line 64, in new_func
    return ctx.invoke(f, obj, *args, **kwargs)
  File "/home/ubuntu/.local/lib/python3.6/site-packages/pipenv/vendor/click/core.py", line 555, in invoke
    return callback(*args, **kwargs)
  File "/home/ubuntu/.local/lib/python3.6/site-packages/pipenv/cli/command.py", line 405, in run
    from ..core import do_run
  File "/home/ubuntu/.local/lib/python3.6/site-packages/pipenv/core.py", line 22, in <module>
    from .project import Project, SourceNotFound
  File "/home/ubuntu/.local/lib/python3.6/site-packages/pipenv/project.py", line 110, in <module>
    raise RuntimeError("Given PIPENV_PIPFILE is not found!")
RuntimeError: Given PIPENV_PIPFILE is not found!
/home/ubuntu/.local/share/virtualenvs/prod-3uuvf-PL/bin/python: can't open file 'main.py': [Errno 2] No such file or directory
